<?xml version="1.0"?>
<robot xmlns:xacro="http://ros.org/wiki/xacro">

  <xacro:property name="radius" value="0.1"/>
  <xacro:property name="length" value="0.05"/>
  <xacro:property name="mass" value="0.1"/>

  <xacro:macro name="wheel_macro" params="parent prefix xyz">

    <joint name="${prefix}_joint" type="continuous">
      <origin xyz="${xyz}" rpy="${radians(-90)} 0 0"/>
      <parent link="${parent}"/>
      <child  link="${prefix}_link"/>
      <axis xyz="0 0 1" />
    </joint>

    <transmission name="${prefix}_trans" type="SimpleTransmission">
      <type>transmission_interface/SimpleTransmission</type>
      <joint name="${prefix}_joint">
        <hardwareInterface>hardware_interface/VelocityJointInterface</hardwareInterface>
      </joint>
      <actuator name="${prefix}_motor">
        <mechanicalReduction>1</mechanicalReduction>
      </actuator>
    </transmission>

    <link name="${prefix}_link">
      <inertial>
       <origin xyz="0 0 0" rpy="0 0 0"/>
       <mass value="${mass}"/>
       <inertia ixx="${mass*(3*(radius**2)+(length**2))/12}" ixy="0.0" ixz="0.0"
                iyy="${mass*(3*(radius**2)+(length**2))/12}" iyz="0.0"
                izz="${(mass*(radius**2))/2}"/>
      </inertial>
      <visual>
        <geometry>
          <cylinder radius="${radius}" length="${length}" />
        </geometry>
        <material name="red"/>
      </visual>
      <collision>
       <geometry>
        <cylinder radius="${radius}" length="${length}"/>
       </geometry>
      </collision>
    </link>

    <gazebo reference="${prefix}_link">
     <material>Gazebo/Red</material>
     <mu1 value="2.5"/>
     <mu2 value="2.5"/>
    </gazebo>

  </xacro:macro>

</robot>
